<mujoco>
  <worldbody>
    <body name="base" pos="0 0 0">
      <geom type="mesh" mesh="gripkit-e1.stl" rgba="0.5 0.5 0.5 1"/>
    </body>

    <body name="finger1" pos="-0.1 0.1 0">
      <joint name="slide1" type="slide" axis="1 0 0" limited="true" range="-0.1 0.1" damping="1"/>
      <geom type="mesh" mesh="finger1.stl" rgba="0.8 0.2 0.2 1"/>
    </body>

    <body name="finger2" pos="0.1 -0.1 0">
      <joint name="slide2" type="slide" axis="0 1 0" limited="true" range="-0.1 0.1" damping="1"/>
      <geom type="mesh" mesh="finger2.stl" rgba="0.2 0.8 0.2 1"/>
    </body>
  </worldbody>
</mujoco>