<mujoco model="ur5">
    <compiler angle="radian" meshdir="ur5" balanceinertia="true"/>
    
    <!-- <option collision="all" -->
    
    <option collision="all" gravity="0 0 -9.81"/>


    <default>
        <light castshadow="false" diffuse="1 1 1" />
        <camera fovy="60" />
    </default>
    <default class="UR5">
        <joint damping='45'/>
    </default>
    <default class="GRIPPER">
        <joint damping='5'/>
    </default>

    <visual>
        <global offwidth="480" offheight="480" />
    </visual>

    <asset>
        <!-- arm models -->
        <mesh file="link0.stl"/>
        <mesh file="link1.stl"/>
        <mesh file="link1_cap.stl" />
        <mesh file="link1_connector.stl" />
        <mesh file="link2.stl" />
        <mesh file="link2_tube.stl" />
        <mesh file="link2_cap.stl" />
        <mesh file="link2_connector.stl" />
        <mesh file="link3a.stl" />
        <mesh file="link3a_connector.stl" />
        <mesh file="link3_tube.stl" />
        <mesh file="link3_cap.stl" />
        <mesh file="link3b.stl" />
        <mesh file="link3b_connector.stl" />
        <mesh file="link3b_connector2.stl"/>
        <mesh file="link4.stl" />
        <mesh file="link4_cap.stl" />
        <mesh file="link4_connector.stl" />
        <mesh file="link5.stl" />
        <mesh file="link5_cap.stl" />
        <mesh file="link5_connector.stl" />
        <mesh file="link6.stl" />
        <mesh file="link6_connector.stl" />

        <mesh file="MHZ2-20D_MHZ2-Body.STL" scale="0.0015 0.0015 0.0015" />
        <mesh file="MHZ2-20D_mhz2-prong.STL" scale="0.0015 0.0015 0.0015" />
        <mesh file="gripper_hat.STL" scale="0.0015 0.0015 0.0015" />

        <!-- <texture name="floor_tile" file="ur5/floor_tile.png" width="3000" height="3000" type="2d"/> -->
        <!-- <material name="tile" texture="floor_tile" specular="0" shininess="0" reflectance="0" emission="1" /> -->
        <material name="silver" specular="1" shininess="0.5" reflectance="1" emission="0.25" rgba="0.70 0.71 0.62 1"/>
        <material name="silver2" specular="1" shininess="0.5" reflectance="1" emission="0.3" rgba="0.82 0.82 0.82 1"/>
        <material name="grey" specular="1" shininess="0.5" reflectance="1" emission="0.1" rgba="0.5 0.5 0.5 1"/>
        <material name="blue" specular="1" shininess="0.5" reflectance="1" emission="0" rgba="0.678 0.847 0.902 1"/>
        <material name="black" specular="1" shininess="0.5" reflectance="1" emission="0" rgba="0.2 0.2 0.2 1"/>
        <material name="white" specular="1" shininess="0.3" reflectance="1" emission="0" rgba="0.9 0.9 0.9 1"/>

        <texture name="floor_tex"   type="2d" builtin="checker" rgb1=".2 .3 .4" rgb2=".1 .2 .3" width="100" height="100" />
        <material name='floor_mat' texture="floor_tex"  shininess="0.8" texrepeat="10 10" specular="0.7"  reflectance="0.5" />
        <texture name="texdenim" type="2d" file="ur5/denim.png"/>
        <material name="matdenim" texture="texdenim"/>
    </asset>

    <worldbody>

        <light name="lightdefault" diffuse=".3 .3 .3" pos="0 0 3" dir="0 0 -1" />
        <camera name="RealSense" mode="fixed" pos="-0.2 0.5 0.8" euler="0 0 3.14" fovy="42.5"/>
        <geom name='floor' material="floor_mat" pos='0 0 0' size='2.5 2.5 0.1'  type='plane' />
        
        <!-- cloth -->
        <body name="B3_5" pos="-0.2 0.5 0.1" >
            <composite type="cloth" count="6 6 1" spacing="0.015" flatinertia="0.01">
                <joint kind="main" damping="0.001"/>
                <skin material="matdenim" texcoord="true" inflate="0.001" subgrid="2"/>
                <geom type="capsule" size="0.015 0.015" />
            </composite>
        </body>
        
         <!-- table  -->
        <body name="table" pos="0 0 0">
            <geom type="box" size="0.7 .7 .1" rgba="1 1 1 1"/>

            <body name="base_link" pos="0 0 0.1">
                <geom name="link0" type="mesh" mesh="link0" pos="0 0 0"/>

                <body name="link1" pos="0 0 0.0213">
                    <joint name="joint0" axis="0 0 1" pos="0 0 0" limited="true" range="-3.14159  3.14159"/>
                    <inertial pos="0 -0.02561 0.00193" mass="3.761" diaginertia="0.1 0.1 0.1"/>
                    <geom name="link1_connector" type="mesh" mesh="link1_connector" pos="0 0 0" material="black"
                        conaffinity="32" contype="32"/>
                    <geom name="link1" type="mesh" mesh="link1" pos="0 0 0.008" material="grey"/>
                    <geom name="link1_cap" type="mesh" mesh="link1_cap" pos="0 0 .1025" material="blue"/>

                    <body name="link2" pos="-0.0663 0 0.0679">
                        <joint name="joint1" axis="-1 0 0" pos="0 0 0" limited="true" range="-3.14159  3.14159"/>
                        <inertial pos="-0.04706 0 0.2125" mass="8.058" diaginertia="0.1 0.1 0.1"/>
                        <geom name="link2_connector" type="mesh" mesh="link2_connector" pos="0 0 0" material="black"
                            conaffinity="32" contype="32"/>
                        <geom name="link2" type="mesh" mesh="link2" pos="-0.008 0 0" material="grey"/>
                        <geom name="link2_cap" type="mesh" mesh="link2_cap" pos="-0.1015 0 -0.0025" material="blue"/>
                        <geom name="link2_tube" type="mesh" mesh="link2_tube" pos="-0.0679 0 0.066" material="silver"/>

                        <body name="link3" pos="-0.008 0 0.425">
                            <joint name="joint2" axis="1 0 0" pos="0 0 0" limited="true" range="-3.14159  3.14159"/>
                            <inertial pos="0.0478 0 0.15" mass="2.846" diaginertia="0.1 0.1 0.1"/>
                            <geom name="link3a_connector" type="mesh" mesh="link3a_connector" pos="0 0 0" material="black"
                                conaffinity="32" contype="32"/>
                            <geom name="link3a" type="mesh" mesh="link3a" pos="0.008 0 0" material="grey"/>
                            <geom name="link3_tube" type="mesh" mesh="link3_tube" pos="0.059 0 0.066" material="silver"/>
                            <geom name="link3b_connector" type="mesh" mesh="link3b_connector" pos="0.059 0 0.3418" material="black" />
                            <geom name="link3b_connector2" type="mesh" mesh="link3b_connector2" pos="0.059 0 0.34" material="grey"
                                conaffinity="32" contype="32"/>
                            <geom name="link3b" type="mesh" mesh="link3b" pos="0.059 0 0.347" material="grey"/>
                            <geom name="link3_cap" type="mesh" mesh="link3_cap" pos="0.0837 0 0.392" material="blue"/>

                            <body name="link4" pos="0.0173 0 0.3922">
                                <joint name="joint3" axis="-1 0 0" pos="0 0 0" limited="true" range="-3.14159  3.14159"/>
                                <inertial pos="-0.05796 -0.0018 0" mass="1.37" diaginertia="0.1 0.1 0.1"/>
                                <geom name="link4_connector" type="mesh" mesh="link4_connector" pos="0 0 0" material="black"
                                    conaffinity="32" contype="32"/>
                                <geom name="link4" type="mesh" mesh="link4" pos="-0.008 0 0" material="grey"/>
                                <geom name="link4_cap" type="mesh" mesh="link4_cap" pos="-0.05325 0 -0.0247" material="blue"/>

                                <body name="link5" pos="-0.05325 0 0.04165">
                                    <joint name="joint4" axis="0 0 1" pos="0 0 0" limited="true" range="-3.14159  3.14159"/>
                                    <inertial pos="0.0018 0 0.01634" mass="1.3" diaginertia="0.1 0.1 0.1"/>
                                    <geom name="link5_connector" type="mesh" mesh="link5_connector" pos="0 0 0" material="black"
                                        conaffinity="32" contype="32"/>
                                    <geom name="link5" type="mesh" mesh="link5" pos="0 0 0.0079" material="grey"/>
                                    <geom name="link5_cap" type="mesh" mesh="link5_cap" pos="0.025 0 0.053" material="blue"/>

                                    <body name="link6" pos="-0.04165 0 0.05305">
                                        <joint name="joint5" axis="-1 0 0" pos="0 0 0" limited="true" range="-3.14159  3.14159"/>
                                        <inertial pos="-0.038841 0 0" mass="0.365" diaginertia="0.1 0.1 0.1"/>
                                        <geom name="link6_connector" type="mesh" mesh="link6_connector" pos="0 0 0" material="black"
                                            conaffinity="32" contype="32"/>
                                        <geom name="link6" type="mesh" mesh="link6" pos="-0.008 0 0" material="silver"/>

                                        <body name="EE" pos="-0.04 0 0" euler="0 0 0"/>
                                            <!--GRIPPER-->
                                            <body name="gripper_body" pos="-0.12 0 0" quat="180 180 0 0" > 
                                                <inertial pos="0 0 0"  mass="0.02" diaginertia="0.1 0.1 0.1" />
                                                <geom name="gripper_body" type="mesh" mesh="MHZ2-20D_MHZ2-Body" material="silver" />

                                                <body name="left_finger" pos="-0.0068 0.02 0" > 
                                                    <inertial pos="0 0 0" mass="0.0045" diaginertia="0.1 0.1 0.1" />
                                                    <geom name="left_finger" type="mesh" material="silver2" mesh="MHZ2-20D_mhz2-prong" />
                                                    <geom name="left_hat" type="mesh" material="white" mesh="gripper_hat" pos="-0.0112 0.0026 0" euler="1.57 0 1.57"/>
                                                    <joint name="joint_lf" class="GRIPPER" type="slide" pos="0 0 0" axis="0 1 0" limited="true" range="-0.008 0" />
                                                </body>
                                                <body name="right_finger" pos="-0.0068 -0.02 0" quat="0 360 0 0">
                                                    <inertial pos="0 0 0" mass="0.0045" diaginertia="0.1 0.1 0.1" />
                                                    <geom name="right_finger" type="mesh" material="silver2" mesh="MHZ2-20D_mhz2-prong" />
                                                    <geom name="gripper_hat" type="mesh" material="black" mesh="gripper_hat" pos="-0.0112 0.0026 0" euler="1.57 0 1.57" />
                                                    <joint name="joint_rf" class="GRIPPER" type="slide" pos="0 0 0" axis="0 1 0" limited="true" range="-0.008 0" />
                                                </body>                                                    
                                            </body>
                                    </body>
                                </body>
                            </body>
                        </body>
                    </body>
                </body>
            </body>
        </body>

    </worldbody>
    <!-- ctrlrange info : https://www.universal-robots.com/articles/ur/robot-care-maintenance/max-joint-torques-cb3-and-e-series/-->
    <actuator>
        <motor  name="joint0_motor" joint="joint0" ctrllimited="true" ctrlrange="-150 150" />
        <motor  name="joint1_motor" joint="joint1" ctrllimited="true" ctrlrange="-150 150" />
        <motor  name="joint2_motor" joint="joint2" ctrllimited="true" ctrlrange="-150 150" />
        <motor name="joint3_motor" joint="joint3" ctrllimited="true" ctrlrange="-28 28" />
        <motor name="joint4_motor" joint="joint4" ctrllimited="true" ctrlrange="-28 28" />
        <motor name="joint5_motor" joint="joint5" ctrllimited="true" ctrlrange="-28 28" />
        <motor name="joint6_rf" joint="joint_lf" ctrllimited="true" ctrlrange="-50 50"/>
        <motor name="joint7_rf" joint="joint_rf" ctrllimited="true" ctrlrange="-50 50"/>
    </actuator>

    <equality>
		<joint name="fingers_1" joint1="joint_lf" joint2="joint_rf" polycoef="0 1 0 0 0" active='true'/>
        <joint name="fingers_2" joint1="joint_rf" joint2="joint_lf" polycoef="0 1 0 0 0" active='true'/>
	</equality>

</mujoco>